Workbook
Name _ftn1: 'Indicator Definitions'!$B$117
Name _ftnref1: 'Indicator Definitions'!$C$26
Name _Ref503791271: 'Social Gradient'!$B$5
Name Areas: #REF!
Name Areas: #REF!
Name Areas: [1]Chart!$S$50:$S$65
Name Areas: #REF!
Name DEA_Indicators: #REF!
Name DEA_Indicators: #REF!
Name DEA_Indicators: #REF!
Name DEA_Indicators: #REF!
Name Gaps: #REF!
Name Gaps: #REF!
Name Gaps: #REF!
Name Gaps: #REF!
Name Indicators: #REF!
Name Indicators: #REF!
Name Indicators: #REF!
Name Indicators: #REF!
Name LGDs: #REF!
Name LGDs: #REF!
Name LGDs: #REF!
Name LGDs: #REF!
Name OnetoFive: #REF!
Name OnetoFive: Information!$G$1:$K$1
Name OnetoFive: #REF!
Name OnetoFive: #REF!
Name Positive_Change: 'Northern Ireland'!$H$220
Name Range1: #REF!
Name Range1: #REF!
Name Range1: 'Northern Ireland'!#REF!
Name Range1: #REF!
Name TwotoFive: #REF!

Sheet Information
J1: 4 | K1: 5
B2: Health Inequalities | E2: Northern Ireland
B3: Annual Report 2025
E4: Health & Social Care Trusts
E5: Belfast
E6: Northern
E7: South Eastern
E8: Southern
E9: Western
E11: Local Government Districts
E12: Antrim & Newtownabbey
B13: Produced by: Public Health Information & Research Branch, Information Analysis Directorate Department of Health Castle Buildings, Belfast BT4 3SQ Tel: 028 905 22501 Email: healthinequalities@health-ni.gov.uk https://www.health-ni.gov.uk/articles/health-inequalities-statistics https://health-ni.gov.uk/topics/dhssps-statistics-and-research/health-inequalities-statistics | E13: Ards & North Down
E14: Armagh City, Banbridge & Craigavon
E15: Belfast
E16: Causeway Coast & Glens
E17: Derry City & Strabane
E18: Fermanagh & Omagh
E19: Lisburn & Castlereagh
E20: Mid & East Antrim
E21: Mid Ulster
E22: Newry, Mourne & Down
E24: Urban Rural Analysis
E25: Social Gradient
E26: Additional Indicators
... E30: Indicator Definitions

Sheet Northern Ireland
A1: NORTHERN IRELAND
A5: Male Life Expectancy at Birth
A6: (Years) | B6: 2017-19 | C6: 2018-20 | D6: 2019-21 | E6: 2020-22 | F6: 2021-23 | G6: Trend Analysis
A7: Northern Ireland | B7: 78.818762 | C7: 78.733213 | D7: 78.476598 | E7: 78.425672 | F7: 78.763745 | G7: =IF(H7="Positive Change",1,IF(H7="Negative Change",-1,IF(H7="No Change",0,""))) -> 0 | H7: No Change
A8: Deprivation Quintiles
A9: 1 (Most Deprived) | B9: 74.715976 | C9: 74.497385 | D9: 73.9308 | E9: 74.04621 | F9: 74.497354 | G9: =IF(H9="Positive Change",1,IF(H9="Negative Change",-1,IF(H9="No Change",0,""))) -> 0 | H9: No Change
A10: 5 (Least Deprived) | B10: 81.70797 | C10: 81.397947 | D10: 81.264003 | E10: 81.24201 | F10: 81.752119 | G10: =IF(H10="Positive Change",1,IF(H10="Negative Change",-1,IF(H10="No Change",0,""))) -> 0 | H10: No Change
A11: Inequality Gaps
A12: Most-Least Deprived | B12: 6.9919939 | C12: 6.9005627 | D12: 7.3332032 | E12: 7.1957996 | F12: 7.2547642 | G12: =IF(H12="Narrowed","►◄",IF(H12="Widened","◄►",IF(H12="No Change","▬",""))) -> ▬ | H12: No Change
A13: Most Deprived-NI | B13: 4.1027858 | C13: 4.2358285 | D13: 4.5457981 | E13: 4.3794616 | F13: 4.2663904 | G13: =IF(H13="Narrowed","►◄",IF(H13="Widened","◄►",IF(H13="No Change","▬",""))) -> ▬ | H13: No Change
A14: SII | B14: 8 | C14: 7.8 | D14: 8.4 | E14: 8.2 | F14: 8.3 | G14: =IF(H14="Narrowed","►◄",IF(H14="Widened","◄►",IF(H14="No Change","▬",""))) -> ▬ | H14: No Change
A16: Female Life Expectancy at Birth
A17: (Years) | B17: 2017-19 | C17: 2018-20 | D17: 2019-21 | E17: 2020-22 | F17: 2021-23 | G17: Trend Analysis
A18: Northern Ireland | B18: 82.58255 | C18: 82.425041 | D18: 82.289751 | E18: 82.255854 | F18: 82.485164 | G18: =IF(H18="Positive Change",1,IF(H18="Negative Change",-1,IF(H18="No Change",0,""))) -> 0 | H18: No Change
A19: Deprivation Quintiles
A20: 1 (Most Deprived) | B20: 79.63464 | C20: 79.274638 | D20: 79.154957 | E20: 79.349267 | F20: 79.339756 | G20: =IF(H20="Positive Change",1,IF(H20="Negative Change",-1,IF(H20="No Change",0,""))) -> 0 | H20: No Change
A21: 5 (Least Deprived) | B21: 84.486238 | C21: 84.316717 | D21: 84.244892 | E21: 84.149349 | F21: 84.513386 | G21: =IF(H21="Positive Change",1,IF(H21="Negative Change",-1,IF(H21="No Change",0,""))) -> 0 | H21: No Change
A22: Inequality Gaps
A23: Most-Least Deprived | B23: 4.8515975 | C23: 5.0420785 | D23: 5.0899348 | E23: 4.8000817 | F23: 5.1736298 | G23: =IF(H23="Narrowed","►◄",IF(H23="Widened","◄►",IF(H23="No Change","▬",""))) -> ▬ | H23: No Change
A24: Most Deprived-NI | B24: 2.94791 | C24: 3.1504026 | D24: 3.134794 | E24: 2.9065867 | F24: 3.1454073 | G24: =IF(H24="Narrowed","►◄",IF(H24="Widened","◄►",IF(H24="No Change","▬",""))) -> ▬ | H24: No Change
A25: SII | B25: 5.5 | C25: 5.6 | D25: 5.8 | E25: 5.7 | F25: 6 | G25: =IF(H25="Narrowed","►◄",IF(H25="Widened","◄►",IF(H25="No Change","▬",""))) -> ◄► | H25: Widened
A27: Male Life Expectancy at Age 65
A28: (Years) | B28: 2017-19 | C28: 2018-20 | D28: 2019-21 | E28: 2020-22 | F28: 2021-23 | G28: Trend Analysis
A29: Northern Ireland | B29: 18.536761 | C29: 18.484435 | D29: 18.365174 | E29: 18.304984 | F29: 18.506212 | G29: =IF(H29="Positive Change",1,IF(H29="Negative Change",-1,IF(H29="No Change",0,""))) -> 0 | H29: No Change
A30: Deprivation Quintiles
A31: 1 (Most Deprived) | B31: 16.74459 | C31: 16.613188 | D31: 16.529334 | E31: 16.481464 | F31: 16.805253 | G31: =IF(H31="Positive Change",1,IF(H31="Negative Change",-1,IF(H31="No Change",0,""))) -> 0 | H31: No Change
A32: 5 (Least Deprived) | B32: 19.821318 | C32: 19.703266 | D32: 19.533884 | E32: 19.430851 | F32: 19.687666 | G32: =IF(H32="Positive Change",1,IF(H32="Negative Change",-1,IF(H32="No Change",0,""))) -> 0 | H32: No Change
A33: Inequality Gaps
A34: Most-Least Deprived | B34: 3.076728 | C34: 3.0900784 | D34: 3.0045507 | E34: 2.9493867 | F34: 2.8824124 | G34: =IF(H34="Narrowed","►◄",IF(H34="Widened","◄►",IF(H34="No Change","▬",""))) -> ▬ | H34: No Change
A35: Most Deprived-NI | B35: 1.7921718 | C35: 1.8712469 | D35: 1.8358398 | E35: 1.8235198 | F35: 1.7009584 | G35: =IF(H35="Narrowed","►◄",IF(H35="Widened","◄►",IF(H35="No Change","▬",""))) -> ▬ | H35: No Change
A36: SII | B36: 3.3402685 | C36: 3.2046693 | D36: 3.1853806 | E36: 3.1907361 | F36: 3.2377876 | G36: =IF(H36="Narrowed","►◄",IF(H36="Widened","◄►",IF(H36="No Change","▬",""))) -> ▬ | H36: No Change
A38: Female Life Expectancy at Age 65
A39: (Years) | B39: 2017-19 | C39: 2018-20 | D39: 2019-21 | E39: 2020-22 | F39: 2021-23 | G39: Trend Analysis
A40: Northern Ireland | B40: 20.856044 | C40: 20.749343 | D40: 20.701913 | E40: 20.57369 | F40: 20.746988 | G40: =IF(H40="Positive Change",1,IF(H40="Negative Change",-1,IF(H40="No Change",0,""))) -> 0 | H40: No Change
A41: Deprivation Quintiles
A42: 1 (Most Deprived) | B42: 19.257098 | C42: 19.027811 | D42: 18.99961 | E42: 18.897149 | F42: 18.990217 | G42: =IF(H42="Positive Change",1,IF(H42="Negative Change",-1,IF(H42="No Change",0,""))) -> 0 | H42: No Change
A43: 5 (Least Deprived) | B43: 21.849085 | C43: 21.743338 | D43: 21.736457 | E43: 21.649448 | F43: 21.985075 | G43: =IF(H43="Positive Change",1,IF(H43="Negative Change",-1,IF(H43="No Change",0,""))) -> 0 | H43: No Change
A44: Inequality Gaps
A45: Most-Least Deprived | B45: 2.591987 | C45: 2.7155272 | D45: 2.7368466 | E45: 2.7522993 | F45: 2.9948589 | G45: =IF(H45="Narrowed","►◄",IF(H45="Widened","◄►",IF(H45="No Change","▬",""))) -> ◄► | H45: Widened
A46: Most Deprived-NI | B46: 1.5989457 | C46: 1.7215322 | D46: 1.7023034 | E46: 1.6765403 | F46: 1.7567717 | G46: =IF(H46="Narrowed","►◄",IF(H46="Widened","◄►",IF(H46="No Change","▬",""))) -> ▬ | H46: No Change
...

Sheet Belfast HSCT
A1: BELFAST HEALTH & SOCIAL CARE TRUST
H3: RAG Comparison
A4: Key: | B4: Worse than | C4: -1 | D4: Similar to | E4: 0 | F4: Better than | G4: 1
A5: Service-based indicators Key: | B5: Lower than | C5: -1 | D5: Similar to | E5: 0 | F5: Higher than | G5: 1
A6: Note: Area values are compared to Northern Ireland, Area's deprived areas are compared to Area Average
A8: Male Life Expectancy at Birth
A9: Years | B9: 2017-19 | C9: 2018-20 | D9: 2019-21 | E9: 2020-22 | F9: 2021-23
A10: Northern Ireland | B10: 78.818762 | C10: 78.733213 | D10: 78.476598 | E10: 78.425672 | F10: 78.763745
A11: Belfast Trust | B11: 76.592157 | C11: 76.358122 | D11: 76.166839 | E11: 76.334529 | F11: 77.124926 | G11: =H11 -> -1 | H11: -1
A12: Belfast Trust Deprived | B12: 70.885571 | C12: 70.562324 | D12: 70.29594 | E12: 70.842728 | F12: 72.042644 | G12: =H12 -> -1 | H12: -1
A13: Belfast Trust-NI Gap | B13: 2.2266053 | C13: 2.375091 | D13: 2.3097583 | E13: 2.0911435 | F13: 1.6388193
A14: Belfast Trust Deprivation Gap | B14: 5.7065857 | C14: 5.795798 | D14: 5.8708994 | E14: 5.4918009 | F14: 5.0822818
A16: Female Life Expectancy at Birth
A17: Years | B17: 2017-19 | C17: 2018-20 | D17: 2019-21 | E17: 2020-22 | F17: 2021-23
A18: Northern Ireland | B18: 82.58255 | C18: 82.425041 | D18: 82.289751 | E18: 82.255854 | F18: 82.485164
A19: Belfast Trust | B19: 81.097893 | C19: 80.726153 | D19: 80.740183 | E19: 80.833244 | F19: 81.095251 | G19: =H19 -> -1 | H19: -1
A20: Belfast Trust Deprived | B20: 76.86615 | C20: 76.262231 | D20: 76.352039 | E20: 76.970588 | F20: 76.691333 | G20: =H20 -> -1 | H20: -1
A21: Belfast Trust-NI Gap | B21: 1.4846572 | C21: 1.6988874 | D21: 1.5495677 | E21: 1.4226102 | F21: 1.3899124
A22: Belfast Trust Deprivation Gap | B22: 4.2317432 | C22: 4.4639228 | D22: 4.3881446 | E22: 3.8626553 | F22: 4.4039183
A24: Male Life Expectancy at Age 65
A25: Years | B25: 2017-19 | C25: 2018-20 | D25: 2019-21 | E25: 2020-22 | F25: 2021-23
A26: Northern Ireland | B26: 18.536761 | C26: 18.484435 | D26: 18.365174 | E26: 18.304984 | F26: 18.506212
A27: Belfast Trust | B27: 17.530418 | C27: 17.243549 | D27: 17.151188 | E27: 17.142029 | F27: 17.565209 | G27: =H27 -> -1 | H27: -1
A28: Belfast Trust Deprived | B28: 15.542331 | C28: 14.954387 | D28: 14.979972 | E28: 15.079483 | F28: 15.68993 | G28: =H28 -> -1 | H28: -1
A29: Belfast Trust-NI Gap | B29: 1.0063435 | C29: 1.2408862 | D29: 1.213986 | E29: 1.162955 | F29: 0.94100248
A30: Belfast Trust Deprivation Gap | B30: 1.9880867 | C30: 2.2891614 | D30: 2.1712156 | E30: 2.0625454 | F30: 1.8752795
A32: Female Life Expectancy at Age 65
A33: Years | B33: 2017-19 | C33: 2018-20 | D33: 2019-21 | E33: 2020-21 | F33: 2021-23
A34: Northern Ireland | B34: 20.856044 | C34: 20.749343 | D34: 20.701913 | E34: 20.57369 | F34: 20.746988
A35: Belfast Trust | B35: 20.113649 | C35: 19.813133 | D35: 19.787306 | E35: 19.661173 | F35: 19.89491 | G35: =H35 -> -1 | H35: -1
A36: Belfast Trust Deprived | B36: 17.890488 | C36: 17.754832 | D36: 17.859873 | E36: 17.984854 | F36: 17.75289 | G36: =H36 -> -1 | H36: -1
A37: Belfast Trust-NI Gap | B37: 0.74239509 | C37: 0.93621035 | D37: 0.91460742 | E37: 0.91251699 | F37: 0.85207816
A38: Belfast Trust Deprivation Gap | B38: 2.2231606 | C38: 2.0583014 | D38: 1.9274324 | E38: 1.6763181 | F38: 2.1420202
A40: Standardised Death Rate - All Deaths
A41: Deaths per 100,000 population | B41: 2017-19 | C41: 2018-20 | D41: 2019-21 | E41: 2020-22 | F41: 2021-23
A42: Northern Ireland | B42: 1004.5825 | C42: 1017.2747 | D42: 1029.771 | E42: 1041.2114 | F42: 1015.538
A43: Belfast Trust | B43: 1124.9628 | C43: 1156.6452 | D43: 1152.4576 | E43: 1165.208 | F43: 1120.7563 | G43: =H43 -> 1 | H43: 1
A44: Belfast Trust Deprived | B44: 1460.36 | C44: 1518.636 | D44: 1523.2532 | E44: 1494.8477 | F44: 1454.362 | G44: =H44 -> 1 | H44: 1
A45: Belfast Trust-NI Gap | B45: 0.11983116 | C45: 0.13700378 | D45: 0.11913969 | E45: 0.11908881 | F45: 0.10360848
A46: Belfast Trust Deprivation Gap | B46: 0.29814071 | C46: 0.31296618 | D46: 0.3217434 | E46: 0.28290201 | F46: 0.29766119
...

Sheet Northern HSCT
A1: NORTHERN HEALTH & SOCIAL CARE TRUST
H3: RAG Comparison
A4: Key: | B4: Worse than | C4: -1 | D4: Similar to | E4: 0 | F4: Better than | G4: 1
A5: Service-based indicators Key: | B5: Lower than | C5: -1 | D5: Similar to | E5: 0 | F5: Higher than | G5: 1
A6: Note: Area values are compared to Northern Ireland, Area's deprived areas are compared to Area Average
A8: Male Life Expectancy at Birth
A9: Years | B9: 2017-19 | C9: 2018-20 | D9: 2019-21 | E9: 2020-22 | F9: 2021-23
A10: Northern Ireland | B10: 78.818762 | C10: 78.733213 | D10: 78.476598 | E10: 78.425672 | F10: 78.763745
A11: Northern Trust | B11: 79.608243 | C11: 79.435878 | D11: 79.078412 | E11: 78.867222 | F11: 79.059918 | G11: =H11 -> 0 | H11: 0
A12: Northern Trust Deprived | B12: 75.890099 | C12: 75.987616 | D12: 75.496494 | E12: 74.979065 | F12: 74.982473 | G12: =H12 -> -1 | H12: -1
A13: Northern Trust-NI Gap | B13: -0.78948116 | C13: -0.70266505 | D13: -0.60181432 | E13: -0.44154996 | F13: -0.29617288
A14: Northern Trust Deprivation Gap | B14: 3.7181447 | C14: 3.4482618 | D14: 3.5819175 | E14: 3.888157 | F14: 4.0774451
A16: Female Life Expectancy at Birth
A17: Years | B17: 2017-19 | C17: 2018-20 | D17: 2019-21 | E17: 2020-22 | F17: 2021-23
A18: Northern Ireland | B18: 82.58255 | C18: 82.425041 | D18: 82.289751 | E18: 82.255854 | F18: 82.485164
A19: Northern Trust | B19: 82.924094 | C19: 82.705832 | D19: 82.718866 | E19: 82.763167 | F19: 83.039077 | G19: =H19 -> 1 | H19: 1
A20: Northern Trust Deprived | B20: 80.389996 | C20: 80.076937 | D20: 80.411047 | E20: 80.559935 | F20: 81.041005 | G20: =H20 -> -1 | H20: -1
A21: Northern Trust-NI Gap | B21: -0.34154338 | C21: -0.28079093 | D21: -0.42911503 | E21: -0.50731321 | F21: -0.55391301
A22: Northern Trust Deprivation Gap | B22: 2.5340977 | C22: 2.6288947 | D22: 2.3078193 | E22: 2.2032323 | F22: 1.9980716
A24: Male Life Expectancy at Age 65
A25: Years | B25: 2017-19 | C25: 2018-20 | D25: 2019-21 | E25: 2020-22 | F25: 2021-23
A26: Northern Ireland | B26: 18.536761 | C26: 18.484435 | D26: 18.365174 | E26: 18.304984 | F26: 18.506212
A27: Northern Trust | B27: 18.763484 | C27: 18.558746 | D27: 18.371541 | E27: 18.37674 | F27: 18.632569 | G27: =H27 -> 0 | H27: 0
A28: Northern Trust Deprived | B28: 16.862671 | C28: 17.087799 | D28: 17.000304 | E28: 16.848475 | F28: 17.055555 | G28: =H28 -> -1 | H28: -1
A29: Northern Trust-NI Gap | B29: -0.22672224 | C29: -0.074311229 | D29: -0.0063677132 | E29: -0.071756396 | F29: -0.12635749
A30: Northern Trust Deprivation Gap | B30: 1.900813 | C30: 1.470947 | D30: 1.3712372 | E30: 1.5282654 | F30: 1.5770139
A32: Female Life Expectancy at Age 65
A33: Years | B33: 2017-19 | C33: 2018-20 | D33: 2019-21 | E33: 2020-22 | F33: 2021-23
A34: Northern Ireland | B34: 20.856044 | C34: 20.749343 | D34: 20.701913 | E34: 20.57369 | F34: 20.746988
A35: Northern Trust | B35: 21.026384 | C35: 20.860514 | D35: 20.853002 | E35: 20.787381 | F35: 21.025012 | G35: =H35 -> 0 | H35: 0
A36: Northern Trust Deprived | B36: 19.98215 | C36: 19.706543 | D36: 19.891518 | E36: 19.673391 | F36: 19.924682 | G36: =H36 -> -1 | H36: -1
A37: Northern Trust-NI Gap | B37: -0.17034035 | C37: -0.11117065 | D37: -0.15108895 | E37: -0.21369113 | F37: -0.27802338
A38: Northern Trust Deprivation Gap | B38: 1.0442341 | C38: 1.1539712 | D38: 0.96148376 | E38: 1.1139897 | F38: 1.1003299
A40: Standardised Death Rate - All Deaths
A41: Deaths per 100,000 population | B41: 2017-19 | C41: 2018-20 | D41: 2019-21 | E41: 2020-22 | F41: 2021-23
A42: Northern Ireland | B42: 1004.5825 | C42: 1017.2747 | D42: 1029.771 | E42: 1041.2114 | F42: 1015.538
A43: Northern Trust | B43: 972.10275 | C43: 997.45642 | D43: 1018.0438 | E43: 1018.8334 | F43: 990.48666 | G43: =H43 -> -1 | H43: -1
A44: Northern Trust Deprived | B44: 1186.4738 | C44: 1191.7405 | D44: 1189.1347 | E44: 1218.6575 | F44: 1190.6002 | G44: =H44 -> 1 | H44: 1
A45: Northern Trust-NI Gap | B45: -0.032331604 | C45: -0.01948176 | D45: -0.011388211 | E45: -0.021492265 | F45: -0.024668049
A46: Northern Trust Deprivation Gap | B46: 0.22052303 | C46: 0.19477948 | D46: 0.16805856 | E46: 0.19613033 | F46: 0.20203557
...

Sheet South Eastern HSCT
A1: SOUTH EASTERN HEALTH & SOCIAL CARE TRUST
H3: RAG Comparison
A4: Key: | B4: Worse than | C4: -1 | D4: Similar to | E4: 0 | F4: Better than | G4: 1
A5: Service-based indicators Key: | B5: Lower than | C5: -1 | D5: Similar to | E5: 0 | F5: Higher than | G5: 1
A6: Note: Area values are compared to Northern Ireland, Area's deprived areas are compared to Area Average
A8: Male Life Expectancy at Birth
A9: Years | B9: 2017-19 | C9: 2018-20 | D9: 2019-21 | E9: 2020-22 | F9: 2021-23
A10: Northern Ireland | B10: 78.818762 | C10: 78.733213 | D10: 78.476598 | E10: 78.425672 | F10: 78.763745
A11: South Eastern Trust | B11: 79.562559 | C11: 79.589949 | D11: 79.530852 | E11: 79.709935 | F11: 79.806534 | G11: =H11 -> 1 | H11: 1
A12: South Eastern Trust Deprived | B12: 75.695257 | C12: 75.899141 | D12: 75.17392 | E12: 75.703942 | F12: 75.469379 | G12: =H12 -> -1 | H12: -1
A13: South Eastern Trust-NI Gap | B13: -0.74379698 | C13: -0.85673597 | D13: -1.0542545 | E13: -1.2842632 | F13: -1.0427893
A14: South Eastern Trust Deprivation Gap | B14: 3.8673021 | C14: 3.6908083 | D14: 4.3569319 | E14: 4.0059933 | F14: 4.3371553
A16: Female Life Expectancy at Birth
A17: Years | B17: 2017-19 | C17: 2018-20 | D17: 2019-21 | E17: 2020-22 | F17: 2021-23
A18: Northern Ireland | B18: 82.58255 | C18: 82.425041 | D18: 82.289751 | E18: 82.255854 | F18: 82.485164
A19: South Eastern Trust | B19: 83.169326 | C19: 82.969657 | D19: 82.90798 | E19: 82.653805 | F19: 82.983856 | G19: =H19 -> 1 | H19: 1
A20: South Eastern Trust Deprived | B20: 81.05906 | C20: 80.753756 | D20: 80.768042 | E20: 80.193609 | F20: 80.472001 | G20: =H20 -> -1 | H20: -1
A21: South Eastern Trust-NI Gap | B21: -0.58677592 | C21: -0.54461594 | D21: -0.61822876 | E21: -0.39795102 | F21: -0.49869249
A22: South Eastern Trust Deprivation Gap | B22: 2.1102666 | C22: 2.2159006 | D22: 2.1399376 | E22: 2.460196 | F22: 2.5118548
A24: Male Life Expectancy at Age 65
A25: Years | B25: 2017-19 | C25: 2018-20 | D25: 2019-21 | E25: 2020-22 | F25: 2021-23
A26: Northern Ireland | B26: 18.536761 | C26: 18.484435 | D26: 18.365174 | E26: 18.304984 | F26: 18.506212
A27: South Eastern Trust | B27: 19.154221 | C27: 19.214089 | D27: 19.18785 | E27: 18.96142 | F27: 19.020012 | G27: =H27 -> 1 | H27: 1
A28: South Eastern Trust Deprived | B28: 17.76063 | C28: 17.901487 | D28: 17.768582 | E28: 17.31915 | F28: 17.34344 | G28: =H28 -> -1 | H28: -1
A29: South Eastern Trust-NI Gap | B29: -0.61745912 | C29: -0.72965459 | D29: -0.82267646 | E29: -0.6564358 | F29: -0.51379998
A30: South Eastern Trust Deprivation Gap | B30: 1.3935907 | C30: 1.3126029 | D30: 1.4192685 | E30: 1.6422698 | F30: 1.6765715
A32: Female Life Expectancy at Age 65
A33: Years | B33: 2017-19 | C33: 2018-20 | D33: 2019-21 | E33: 2020-22 | F33: 2021-23
A34: Northern Ireland | B34: 20.856044 | C34: 20.749343 | D34: 20.701913 | E34: 20.57369 | F34: 20.746988
A35: South Eastern Trust | B35: 21.25494 | C35: 21.105019 | D35: 21.172804 | E35: 20.980155 | F35: 21.156416 | G35: =H35 -> 1 | H35: 1
A36: South Eastern Trust Deprived | B36: 20.188323 | C36: 19.863534 | D36: 20.280362 | E36: 19.898038 | F36: 20.219529 | G36: =H36 -> -1 | H36: -1
A37: South Eastern Trust-NI Gap | B37: -0.39889652 | C37: -0.35567582 | D37: -0.47089058 | E37: -0.40646501 | F37: -0.40942749
A38: South Eastern Trust Deprivation Gap | B38: 1.0666167 | C38: 1.2414856 | D38: 0.89244228 | E38: 1.0821164 | F38: 0.93688683
A40: Standardised Death Rate - All Deaths
A41: Deaths per 100,000 population | B41: 2017-19 | C41: 2018-20 | D41: 2019-21 | E41: 2020-22 | F41: 2021-23
A42: Northern Ireland | B42: 1004.5825 | C42: 1017.2747 | D42: 1029.771 | E42: 1041.2114 | F42: 1015.538
A43: South Eastern Trust | B43: 946.34203 | C43: 953.59015 | D43: 968.55586 | E43: 975.57582 | F43: 955.16997 | G43: =H43 -> -1 | H43: -1
A44: South Eastern Trust Deprived | B44: 1110.4897 | C44: 1122.2541 | D44: 1129.9072 | E44: 1164.8001 | F44: 1134.4397 | G44: =H44 -> 1 | H44: 1
A45: South Eastern Trust-NI Gap | B45: -0.057974806 | C45: -0.062603122 | D45: -0.059445391 | E45: -0.063037681 | F45: -0.05944438
A46: South Eastern Trust Deprivation Gap | B46: 0.17345488 | C46: 0.1768726 | D46: 0.1665896 | E46: 0.19396161 | F46: 0.1876836
...

Sheet Southern HSCT
A1: SOUTHERN HEALTH & SOCIAL CARE TRUST
H3: RAG Comparison
A4: Key: | B4: Worse than | C4: -1 | D4: Similar to | E4: 0 | F4: Better than | G4: 1
A5: Service-based indicators Key: | B5: Lower than | C5: -1 | D5: Similar to | E5: 0 | F5: Higher than | G5: 1
A6: Note: Area values are compared to Northern Ireland, Area's deprived areas are compared to Area Average
A8: Male Life Expectancy at Birth
A9: Years | B9: 2017-19 | C9: 2018-20 | D9: 2019-21 | E9: 2020-22 | F9: 2021-23
A10: Northern Ireland | B10: 78.818762 | C10: 78.733213 | D10: 78.476598 | E10: 78.425672 | F10: 78.763745
A11: Southern Trust | B11: 79.405423 | C11: 79.344988 | D11: 79.10429 | E11: 78.66565 | F11: 79.065624 | G11: =H11 -> 0 | H11: 0
A12: Southern Trust Deprived | B12: 77.260524 | C12: 76.671233 | D12: 75.96629 | E12: 75.796638 | F12: 75.822596 | G12: =H12 -> -1 | H12: -1
A13: Southern Trust-NI Gap | B13: -0.58666124 | C13: -0.61177451 | D13: -0.62769215 | E13: -0.23997779 | F13: -0.30187886
A14: Southern Trust Deprivation Gap | B14: 2.1448993 | C14: 2.6737545 | D14: 3.1379995 | E14: 2.869012 | F14: 3.2430274
A16: Female Life Expectancy at Birth
A17: Years | B17: 2017-19 | C17: 2018-20 | D17: 2019-21 | E17: 2020-22 | F17: 2021-23
A18: Northern Ireland | B18: 82.58255 | C18: 82.425041 | D18: 82.289751 | E18: 82.255854 | F18: 82.485164
A19: Southern Trust | B19: 83.175859 | C19: 83.214141 | D19: 82.969422 | E19: 82.721713 | F19: 82.958503 | G19: =H19 -> 1 | H19: 1
A20: Southern Trust Deprived | B20: 81.751483 | C20: 82.125026 | D20: 81.404088 | E20: 81.707097 | F20: 81.40286 | G20: =H20 -> -1 | H20: -1
A21: Southern Trust-NI Gap | B21: -0.59330867 | C21: -0.78910021 | D21: -0.67967127 | E21: -0.46585948 | F21: -0.47333906
A22: Southern Trust Deprivation Gap | B22: 1.424376 | C22: 1.0891154 | D22: 1.5653345 | E22: 1.0146163 | F22: 1.5556428
A24: Male Life Expectancy at Age 65
A25: Years | B25: 2017-19 | C25: 2018-20 | D25: 2019-21 | E25: 2020-22 | F25: 2021-23
A26: Northern Ireland | B26: 18.536761 | C26: 18.484435 | D26: 18.365174 | E26: 18.304984 | F26: 18.506212
A27: Southern Trust | B27: 18.574939 | C27: 18.686069 | D27: 18.617791 | E27: 18.507819 | F27: 18.699653 | G27: =H27 -> 0 | H27: 0
A28: Southern Trust Deprived | B28: 17.277277 | C28: 17.228077 | D28: 16.8264 | E28: 17.014879 | F28: 17.079739 | G28: =H28 -> -1 | H28: -1
A29: Southern Trust-NI Gap | B29: -0.038177927 | C29: -0.20163445 | D29: -0.25261778 | E29: -0.20283479 | F29: -0.19344167
A30: Southern Trust Deprivation Gap | B30: 1.2976628 | C30: 1.4579928 | D30: 1.7913917 | E30: 1.4929394 | F30: 1.6199139
A32: Female Life Expectancy at Age 65
A33: Years | B33: 2017-19 | C33: 2018-20 | D33: 2019-21 | E33: 2020-22 | F33: 2021-23
A34: Northern Ireland | B34: 20.856044 | C34: 20.749343 | D34: 20.701913 | E34: 20.57369 | F34: 20.746988
A35: Southern Trust | B35: 21.126046 | C35: 21.213604 | D35: 21.075922 | E35: 20.862272 | F35: 20.994985 | G35: =H35 -> 0 | H35: 0
A36: Southern Trust Deprived | B36: 20.347615 | C36: 20.902469 | D36: 19.996345 | E36: 19.952205 | F36: 19.815658 | G36: =H36 -> -1 | H36: -1
A37: Southern Trust-NI Gap | B37: -0.2700025 | C37: -0.46426039 | D37: -0.37400855 | E37: -0.28858277 | F37: -0.24799711
A38: Southern Trust Deprivation Gap | B38: 0.77843135 | C38: 0.31113488 | D38: 1.0795769 | E38: 0.91006712 | F38: 1.1793275
A40: Standardised Death Rate - All Deaths
A41: Deaths per 100,000 population | B41: 2017-19 | C41: 2018-20 | D41: 2019-21 | E41: 2020-22 | F41: 2021-23
A42: Northern Ireland | B42: 1004.5825 | C42: 1017.2747 | D42: 1029.771 | E42: 1041.2114 | F42: 1015.538
A43: Southern Trust | B43: 974.09797 | C43: 971.15017 | D43: 998.1612 | E43: 1011.7873 | F43: 990.68731 | G43: =H43 -> -1 | H43: -1
A44: Southern Trust Deprived | B44: 1099.3246 | C44: 1110.5101 | D44: 1188.5129 | E44: 1177.3945 | F44: 1183.2658 | G44: =H44 -> 1 | H44: 1
A45: Southern Trust-NI Gap | B45: -0.030345479 | C45: -0.045341293 | D45: -0.030695953 | E45: -0.02825945 | F45: -0.024470464
A46: Southern Trust Deprivation Gap | B46: 0.12855652 | C46: 0.14349984 | D46: 0.1907024 | E46: 0.1636779 | F46: 0.19438877
...

Sheet Western HSCT
A1: WESTERN HEALTH & SOCIAL CARE TRUST
H3: RAG Comparison
A4: Key: | B4: Worse than | C4: -1 | D4: Similar to | E4: 0 | F4: Better than | G4: 1
A5: Service-based indicators Key: | B5: Lower than | C5: -1 | D5: Similar to | E5: 0 | F5: Higher than | G5: 1
A6: Note: Area values are compared to Northern Ireland, Area's deprived areas are compared to Area Average
A8: Male Life Expectancy at Birth
A9: Years | B9: 2017-19 | C9: 2018-20 | D9: 2019-21 | E9: 2020-22 | F9: 2021-23
A10: Northern Ireland | B10: 78.818762 | C10: 78.733213 | D10: 78.476598 | E10: 78.425672 | F10: 78.763745
A11: Western Trust | B11: 78.485506 | C11: 78.570198 | D11: 78.12206 | E11: 78.249362 | F11: 78.424942 | G11: =H11 -> 0 | H11: 0
A12: Western Trust Deprived | B12: 74.046836 | C12: 74.126404 | D12: 73.288405 | E12: 73.249613 | F12: 73.967538 | G12: =H12 -> -1 | H12: -1
A13: Western Trust-NI Gap | B13: 0.33325634 | C13: 0.16301564 | D13: 0.35453741 | E13: 0.17630964 | F13: 0.33880287
A14: Western Trust Deprivation Gap | B14: 4.4386698 | C14: 4.4437939 | D14: 4.8336556 | E14: 4.9997491 | F14: 4.4574042
A16: Female Life Expectancy at Birth
A17: Years | B17: 2017-19 | C17: 2018-20 | D17: 2019-21 | E17: 2020-22 | F17: 2021-23
A18: Northern Ireland | B18: 82.58255 | C18: 82.425041 | D18: 82.289751 | E18: 82.255854 | F18: 82.485164
A19: Western Trust | B19: 82.271146 | C19: 82.309954 | D19: 81.771441 | E19: 81.991625 | F19: 81.960356 | G19: =H19 -> -1 | H19: -1
A20: Western Trust Deprived | B20: 79.502271 | C20: 79.514877 | D20: 79.105307 | E20: 79.291443 | F20: 78.661938 | G20: =H20 -> -1 | H20: -1
A21: Western Trust-NI Gap | B21: 0.31140462 | C21: 0.11508652 | D21: 0.51831011 | E21: 0.26422904 | F21: 0.52480717
A22: Western Trust Deprivation Gap | B22: 2.7688751 | C22: 2.795077 | D22: 2.6661343 | E22: 2.7001818 | F22: 3.2984185
A24: Male Life Expectancy at Age 65
A25: Years | B25: 2017-19 | C25: 2018-20 | D25: 2019-21 | E25: 2020-22 | F25: 2021-23
A26: Northern Ireland | B26: 18.536761 | C26: 18.484435 | D26: 18.365174 | E26: 18.304984 | F26: 18.506212
A27: Western Trust | B27: 18.367568 | C27: 18.5042 | D27: 18.278855 | E27: 18.289043 | F27: 18.342244 | G27: =H27 -> 0 | H27: 0
A28: Western Trust Deprived | B28: 16.696286 | C28: 16.995129 | D28: 16.962021 | E28: 16.730963 | F28: 16.940257 | G28: =H28 -> -1 | H28: -1
A29: Western Trust-NI Gap | B29: 0.16919344 | C29: -0.019764647 | D29: 0.086318373 | E29: 0.015940716 | F29: 0.16396749
A30: Western Trust Deprivation Gap | B30: 1.6712818 | C30: 1.5090705 | D30: 1.3168337 | E30: 1.5580803 | F30: 1.4019876
A32: Female Life Expectancy at Age 65
A33: Years | B33: 2017-19 | C33: 2018-20 | D33: 2019-21 | E33: 2020-22 | F33: 2021-23
A34: Northern Ireland | B34: 20.856044 | C34: 20.749343 | D34: 20.701913 | E34: 20.57369 | F34: 20.746988
A35: Western Trust | B35: 20.538221 | C35: 20.587319 | D35: 20.381907 | E35: 20.31826 | F35: 20.350372 | G35: =H35 -> -1 | H35: -1
A36: Western Trust Deprived | B36: 18.987026 | C36: 18.892553 | D36: 18.66781 | E36: 18.776378 | F36: 18.849792 | G36: =H36 -> -1 | H36: -1
A37: Western Trust-NI Gap | B37: 0.31782309 | C37: 0.16202459 | D37: 0.32000623 | E37: 0.25542921 | F37: 0.39661662
A38: Western Trust Deprivation Gap | B38: 1.5511948 | C38: 1.6947657 | D38: 1.7140974 | E38: 1.5418823 | F38: 1.5005794
A40: Standardised Death Rate - All Deaths
A41: Deaths per 100,000 population | B41: 2017-19 | C41: 2018-20 | D41: 2019-21 | E41: 2020-22 | F41: 2021-23
A42: Northern Ireland | B42: 1004.5825 | C42: 1017.2747 | D42: 1029.771 | E42: 1041.2114 | F42: 1015.538
A43: Western Trust | B43: 1042.3577 | C43: 1038.3939 | D43: 1075.2145 | E43: 1070.1419 | F43: 1059.8229 | G43: =H43 -> 1 | H43: 1
A44: Western Trust Deprived | B44: 1331.1122 | C44: 1346.8271 | D44: 1357.2557 | E44: 1350.7074 | F44: 1322.8697 | G44: =H44 -> 1 | H44: 1
A45: Western Trust-NI Gap | B45: 0.03760292 | C45: 0.020760583 | D45: 0.044129743 | E45: 0.027785466 | F45: 0.043607343
A46: Western Trust Deprivation Gap | B46: 0.27702051 | C46: 0.29702907 | D46: 0.26231149 | E46: 0.26217598 | F46: 0.24819878
...

Sheet Antrim & Newtownabbey
A1: ANTRIM & NEWTOWNABBEY LOCAL GOVERNMENT DISTRICT
H3: RAG Comparison
A4: Key: | B4: Worse than | C4: -1 | D4: Similar to | E4: 0 | F4: Better than | G4: 1
A5: Service-based indicators Key: | B5: Lower than | C5: -1 | D5: Similar to | E5: 0 | F5: Higher than | G5: 1
A6: Note: Area values are compared to Northern Ireland, Area's deprived areas are compared to Area Average
A8: Male Life Expectancy at Birth
A9: Years | B9: 2017-19 | C9: 2018-20 | D9: 2019-21 | E9: 2020-22 | F9: 2021-23
A10: Northern Ireland | B10: 78.818762 | C10: 78.733213 | D10: 78.476598 | E10: 78.425672 | F10: 78.763745
A11: Antrim & Newtownabbey LGD | B11: 79.683862 | C11: 79.013653 | D11: 78.757014 | E11: 78.719966 | F11: 79.223327 | G11: =H11 -> 0 | H11: 0
A12: Antrim & Newtownabbey LGD Deprived | B12: 75.45448 | C12: 74.835921 | D12: 75.189007 | E12: 75.438632 | F12: 75.569359 | G12: =H12 -> -1 | H12: -1
A13: Antrim & Newtownabbey LGD-NI Gap | B13: -0.86509982 | C13: -0.28044021 | D13: -0.28041677 | E13: -0.29429386 | F13: -0.45958248
A14: Antrim & Newtownabbey LGD Deprivation Gap | B14: 4.2293823 | C14: 4.1777326 | D14: 3.5680079 | E14: 3.2813342 | F14: 3.6539679
A15: Airport | B15: 82.788415 | C15: 81.560015 | D15: 81.123642 | E15: 80.842985 | F15: 81.862547 | H15: 1
A16: Antrim | B16: 77.359624 | C16: 76.594081 | D16: 76.931081 | E16: 77.193961 | F16: 77.617367 | H16: 0
A17: Ballyclare | B17: 81.601868 | C17: 80.321024 | D17: 79.659637 | E17: 79.62262 | F17: 79.920877 | H17: 0
A18: Dunsilly | B18: 80.302373 | C18: 81.181082 | D18: 80.480063 | E18: 79.60918 | F18: 80.285869 | H18: 0
A19: Glengormley Urban | B19: 79.876864 | C19: 79.29165 | D19: 79.85423 | E19: 80.885388 | F19: 80.613227 | H19: 0
A20: Macedon | B20: 75.367619 | C20: 74.96272 | D20: 74.479284 | E20: 74.992909 | F20: 75.623429 | H20: -1
A21: Three Mile Water | B21: 83.865958 | C21: 82.329727 | D21: 80.723068 | E21: 79.72665 | F21: 80.415823 | H21: 0
A23: Female Life Expectancy at Birth
A24: Years | B24: 2017-19 | C24: 2018-20 | D24: 2019-21 | E24: 2020-22 | F24: 2021-23
A25: Northern Ireland | B25: 82.58255 | C25: 82.425041 | D25: 82.289751 | E25: 82.255854 | F25: 82.485164
A26: Antrim & Newtownabbey LGD | B26: 82.730888 | C26: 82.627959 | D26: 82.79415 | E26: 82.522135 | F26: 82.737633 | G26: =H26 -> 0 | H26: 0
A27: Antrim & Newtownabbey LGD Deprived | B27: 79.345843 | C27: 79.453445 | D27: 80.199326 | E27: 79.851339 | F27: 80.706263 | G27: =H27 -> -1 | H27: -1
A28: Antrim & Newtownabbey LGD-NI Gap | B28: -0.14833802 | C28: -0.20291846 | D28: -0.5043986 | E28: -0.26628148 | F28: -0.2524698
A29: Antrim & Newtownabbey LGD Deprivation Gap | B29: 3.3850452 | C29: 3.1745143 | D29: 2.594824 | E29: 2.6707965 | F29: 2.0313708
A30: Airport | B30: 83.416006 | C30: 83.90618 | D30: 83.908041 | E30: 83.5997 | F30: 83.961441 | H30: 0
A31: Antrim | B31: 81.104944 | C31: 81.767994 | D31: 81.653835 | E31: 81.87682 | F31: 81.406954 | H31: 0
A32: Ballyclare | B32: 84.518521 | C32: 84.221195 | D32: 83.623772 | E32: 83.086591 | F32: 82.499868 | H32: 0
A33: Dunsilly | B33: 81.504121 | C33: 81.701627 | D33: 82.579229 | E33: 82.671746 | F33: 82.976956 | H33: 0
A34: Glengormley Urban | B34: 84.900956 | C34: 83.635508 | D34: 82.942345 | E34: 82.595041 | F34: 83.16387 | H34: 0
A35: Macedon | B35: 80.663919 | C35: 80.560684 | D35: 81.133765 | E35: 80.119172 | F35: 80.761988 | H35: -1
A36: Three Mile Water | B36: 87.523791 | C36: 86.256739 | D36: 87.657921 | E36: 86.391783 | F36: 87.092865 | H36: 1
A38: Male Life Expectancy at Age 65
A39: Years | B39: 2017-19 | C39: 2018-20 | D39: 2019-21 | E39: 2020-22 | F39: 2021-23
A40: Northern Ireland | B40: 18.536761 | C40: 18.484435 | D40: 18.365174 | E40: 18.304984 | F40: 18.506212
A41: Antrim & Newtownabbey LGD | B41: 18.654186 | C41: 18.206652 | D41: 18.150519 | E41: 18.363092 | F41: 18.893278 | G41: =H41 -> 0 | H41: 0
A42: Antrim & Newtownabbey LGD Deprived | B42: 15.978453 | C42: 16.069463 | D42: 16.304064 | E42: 16.386397 | F42: 17.033659 | G42: =H42 -> -1 | H42: -1
A43: Antrim & Newtownabbey LGD-NI Gap | B43: -0.11742479 | C43: 0.27778305 | D43: 0.21465494 | E43: -0.058108044 | F43: -0.38706654
A44: Antrim & Newtownabbey LGD Deprivation Gap | B44: 2.6757333 | C44: 2.1371891 | D44: 1.8464546 | E44: 1.976695 | F44: 1.8596189
...

Sheet Ards & North Down
A1: ARDS & NORTH DOWN LOCAL GOVERNMENT DISTRICT
H3: RAG Comparison
A4: Key: | B4: Worse than | C4: -1 | D4: Similar to | E4: 0 | F4: Better than | G4: 1
A5: Service-based indicators Key: | B5: Lower than | C5: -1 | D5: Similar to | E5: 0 | F5: Higher than | G5: 1
A6: Note: Area values are compared to Northern Ireland, Area's deprived areas are compared to Area Average
A8: Male Life Expectancy at Birth
A9: Years | B9: 2017-19 | C9: 2018-20 | D9: 2019-21 | E9: 2020-22 | F9: 2021-23
A10: Northern Ireland | B10: 78.818762 | C10: 78.733213 | D10: 78.476598 | E10: 78.425672 | F10: 78.763745
A11: Ards & North Down LGD | B11: 79.735765 | C11: 79.803792 | D11: 79.914898 | E11: 80.011269 | F11: 79.906582 | G11: =H11 -> 1 | H11: 1
A12: Ards & North Down LGD Deprived | B12: 76.117045 | C12: 76.512961 | D12: 76.38883 | E12: 77.190765 | F12: 76.237518 | G12: =H12 -> -1 | H12: -1
A13: Ards & North Down LGD-NI Gap | B13: -0.91700326 | C13: -1.0705787 | D13: -1.4383002 | E13: -1.5855969 | F13: -1.1428371
A14: Ards & North Down LGD Deprivation Gap | B14: 3.6187206 | C14: 3.2908305 | D14: 3.5260683 | E14: 2.8205041 | F14: 3.6690637
A15: Ards Peninsula | B15: 80.971912 | C15: 80.415367 | D15: 80.256181 | E15: 80.649041 | F15: 80.030178 | H15: 0
A16: Bangor Central | B16: 78.663041 | C16: 78.941269 | D16: 79.412113 | E16: 80.582856 | F16: 80.065103 | H16: 0
A17: Bangor East And Donaghadee | B17: 80.689466 | C17: 80.154587 | D17: 80.527578 | E17: 80.339567 | F17: 81.52032 | H17: 0
A18: Bangor West | B18: 78.970317 | C18: 78.24497 | D18: 78.911592 | E18: 78.849476 | F18: 79.51772 | H18: 0
A19: Comber | B19: 81.218108 | C19: 81.321869 | D19: 80.277649 | E19: 80.586739 | F19: 80.508504 | H19: 0
A20: Holywood And Clandeboye | B20: 81.000034 | C20: 81.901883 | D20: 82.61678 | E20: 81.130952 | F20: 80.598626 | H20: 0
A21: Newtownards | B21: 77.962073 | C21: 78.459537 | D21: 78.393865 | E21: 78.569728 | F21: 78.027316 | H21: 0
A23: Female Life Expectancy at Birth
A24: Years | B24: 2017-19 | C24: 2018-20 | D24: 2019-21 | E24: 2020-22 | F24: 2021-23
A25: Northern Ireland | B25: 82.58255 | C25: 82.425041 | D25: 82.289751 | E25: 82.255854 | F25: 82.485164
A26: Ards & North Down LGD | B26: 82.962882 | C26: 82.782214 | D26: 82.827251 | E26: 82.871865 | F26: 83.413226 | G26: =H26 -> 1 | H26: 1
A27: Ards & North Down LGD Deprived | B27: 79.911702 | C27: 79.840217 | D27: 80.30288 | E27: 80.968899 | F27: 81.527434 | G27: =H27 -> -1 | H27: -1
A28: Ards & North Down LGD-NI Gap | B28: -0.38033129 | C28: -0.35717341 | D28: -0.53749952 | E28: -0.61601128 | F28: -0.92806184
A29: Ards & North Down LGD Deprivation Gap | B29: 3.0511799 | C29: 2.9419968 | D29: 2.5243702 | E29: 1.9029662 | F29: 1.8857911
A30: Ards Peninsula | B30: 83.335617 | C30: 83.944843 | D30: 84.166948 | E30: 84.151479 | F30: 83.693833 | H30: 0
A31: Bangor Central | B31: 83.23781 | C31: 82.058568 | D31: 82.29085 | E31: 82.402897 | F31: 83.678944 | H31: 0
A32: Bangor East And Donaghadee | B32: 83.367767 | C32: 84.952664 | D32: 85.072993 | E32: 84.558492 | F32: 83.103713 | H32: 0
A33: Bangor West | B33: 81.109134 | C33: 81.047473 | D33: 80.796873 | E33: 81.097909 | F33: 81.86597 | H33: 0
A34: Comber | B34: 84.405583 | C34: 84.883601 | D34: 84.725499 | E34: 83.907144 | F34: 83.935397 | H34: 0
A35: Holywood And Clandeboye | B35: 84.404736 | C35: 82.520774 | D35: 82.480856 | E35: 82.759353 | F35: 84.669452 | H35: 0
A36: Newtownards | B36: 81.895983 | C36: 81.529949 | D36: 81.436824 | E36: 82.055891 | F36: 83.347837 | H36: 0
A38: Male Life Expectancy at Age 65
A39: Years | B39: 2017-19 | C39: 2018-20 | D39: 2019-21 | E39: 2020-22 | F39: 2021-23
A40: Northern Ireland | B40: 18.536761 | C40: 18.484435 | D40: 18.365174 | E40: 18.304984 | F40: 18.506212
A41: Ards & North Down LGD | B41: 19.372194 | C41: 19.306664 | D41: 19.409057 | E41: 19.657964 | F41: 19.09564 | G41: =H41 -> 1 | H41: 1
A42: Ards & North Down LGD Deprived | B42: 17.370615 | C42: 17.565086 | D42: 17.61158 | E42: 17.508337 | F42: 17.060392 | G42: =H42 -> -1 | H42: -1
A43: Ards & North Down LGD-NI Gap | B43: -0.83543305 | C43: -0.82222909 | D43: -1.0438838 | E43: -1.3529806 | F43: -0.5894281
A44: Ards & North Down LGD Deprivation Gap | B44: 2.0015792 | C44: 1.7415781 | D44: 1.7974773 | E44: 2.149627 | F44: 2.035248
...

Sheet Armagh, Banbridge & Craigavon
A1: ARMAGH CITY, BANBRIDGE & CRAIGAVON LOCAL GOVERNMENT DISTRICT
H3: RAG Comparison
A4: Key: | B4: Worse than | C4: -1 | D4: Similar to | E4: 0 | F4: Better than | G4: 1
A5: Service-based indicators Key: | B5: Lower than | C5: -1 | D5: Similar to | E5: 0 | F5: Higher than | G5: 1
A6: Note: Area values are compared to Northern Ireland, Area's deprived areas are compared to Area Average
A8: Male Life Expectancy at Birth
A9: Years | B9: 2017-19 | C9: 2018-20 | D9: 2019-21 | E9: 2020-22 | F9: 2021-23
A10: Northern Ireland | B10: 78.818762 | C10: 78.733213 | D10: 78.476598 | E10: 78.425672 | F10: 78.763745
A11: Armagh City, Banbridge & Craigavon LGD | B11: 79.539814 | C11: 79.395949 | D11: 79.246134 | E11: 78.765945 | F11: 79.156333 | G11: =H11 -> 0 | H11: 0
A12: Armagh City, Banbridge & Craigavon LGD Deprived | B12: 76.423444 | C12: 76.490017 | D12: 76.068664 | E12: 75.851083 | F12: 75.707744 | G12: =H12 -> -1 | H12: -1
A13: Armagh City, Banbridge & Craigavon LGD-NI Gap | B13: -0.72105215 | C13: -0.66273538 | D13: -0.76953597 | E13: -0.34027264 | F13: -0.39258818
A14: Armagh City, Banbridge & Craigavon LGD Deprivation Gap | B14: 3.1163704 | C14: 2.9059313 | D14: 3.1774693 | E14: 2.9148615 | F14: 3.4485894
A15: Armagh | B15: 80.269939 | C15: 80.387491 | D15: 79.71447 | E15: 78.625663 | F15: 78.102733 | H15: 0
A16: Banbridge | B16: 80.326327 | C16: 79.582715 | D16: 79.742159 | E16: 79.025437 | F16: 79.566454 | H16: 0
A17: Craigavon | B17: 79.825519 | C17: 80.149618 | D17: 79.730414 | E17: 78.733975 | F17: 79.38749 | H17: 0
A18: Cusher | B18: 81.109778 | C18: 81.069294 | D18: 80.45347 | E18: 80.225736 | F18: 80.530571 | H18: 0
A19: Lagan River | B19: 81.391402 | C19: 80.889525 | D19: 81.135577 | E19: 81.617459 | F19: 82.823125 | H19: 1
A20: Lurgan | B20: 77.77869 | C20: 77.666492 | D20: 77.772345 | E20: 77.616867 | F20: 77.818824 | H20: 0
A21: Portadown | B21: 77.231247 | C21: 77.389448 | D21: 77.388639 | E21: 77.010998 | F21: 77.93636 | H21: 0
A23: Female Life Expectancy at Birth
A24: Years | B24: 2017-19 | C24: 2018-20 | D24: 2019-21 | E24: 2020-22 | F24: 2021-23
A25: Northern Ireland | B25: 82.58255 | C25: 82.425041 | D25: 82.289751 | E25: 82.255854 | F25: 82.485164
A26: Armagh City, Banbridge & Craigavon LGD | B26: 83.212595 | C26: 83.329746 | D26: 83.077759 | E26: 82.821234 | F26: 82.97564 | G26: =H26 -> 0 | H26: 0
A27: Armagh City, Banbridge & Craigavon LGD Deprived | B27: 81.633552 | C27: 82.591636 | D27: 81.839911 | E27: 81.623609 | F27: 81.923104 | G27: =H27 -> 0 | H27: 0
A28: Armagh City, Banbridge & Craigavon LGD-NI Gap | B28: -0.63004503 | C28: -0.90470504 | D28: -0.78800808 | E28: -0.5653796 | F28: -0.49047587
A29: Armagh City, Banbridge & Craigavon LGD Deprivation Gap | B29: 1.5790429 | C29: 0.73811001 | D29: 1.2378479 | E29: 1.1976246 | F29: 1.0525352
A30: Armagh | B30: 82.148847 | C30: 82.603571 | D30: 82.592948 | E30: 82.349417 | F30: 82.856718 | H30: 0
A31: Banbridge | B31: 83.338383 | C31: 82.796576 | D31: 82.278971 | E31: 81.800761 | F31: 82.432646 | H31: 0
A32: Craigavon | B32: 82.839576 | C32: 83.634069 | D32: 82.984131 | E32: 83.149633 | F32: 83.409452 | H32: 0
A33: Cusher | B33: 84.111338 | C33: 84.657342 | D33: 84.434056 | E33: 84.176198 | F33: 83.514602 | H33: 0
A34: Lagan River | B34: 85.428974 | C34: 85.69702 | D34: 85.302523 | E34: 85.422116 | F34: 85.458533 | H34: 1
A35: Lurgan | B35: 84.037285 | C35: 84.205822 | D35: 82.995869 | E35: 82.146426 | F35: 81.948801 | H35: 0
A36: Portadown | B36: 81.84222 | C36: 81.179475 | D36: 82.049738 | E36: 82.277759 | F36: 82.693596 | H36: 0
A38: Male Life Expectancy at Age 65
A39: Years | B39: 2017-19 | C39: 2018-20 | D39: 2019-21 | E39: 2020-22 | F39: 2021-23
A40: Northern Ireland | B40: 18.536761 | C40: 18.484435 | D40: 18.365174 | E40: 18.304984 | F40: 18.506212
A41: Armagh City, Banbridge & Craigavon LGD | B41: 18.749983 | C41: 18.792466 | D41: 18.701837 | E41: 18.908061 | F41: 18.907432 | G41: =H41 -> 0 | H41: 0
A42: Armagh City, Banbridge & Craigavon LGD Deprived | B42: 17.310411 | C42: 17.352002 | D42: 17.225361 | E42: 17.217415 | F42: 17.257314 | G42: =H42 -> -1 | H42: -1
A43: Armagh City, Banbridge & Craigavon LGD-NI Gap | B43: -0.21322183 | C43: -0.30803077 | D43: -0.33666294 | E43: -0.60307737 | F43: -0.40122012
A44: Armagh City, Banbridge & Craigavon LGD Deprivation Gap | B44: 1.4395726 | C44: 1.4404632 | D44: 1.4764752 | E44: 1.6906457 | F44: 1.6501172
...

Sheet Belfast LGD
A1: BELFAST LOCAL GOVERNMENT DISTRICT
H3: RAG Comparison
A4: Key: | B4: Worse than | C4: -1 | D4: Similar to | E4: 0 | F4: Better than | G4: 1
A5: Service-based indicators Key: | B5: Lower than | C5: -1 | D5: Similar to | E5: 0 | F5: Higher than | G5: 1
A6: Note: Area values are compared to Northern Ireland, Area's deprived areas are compared to Area Average
A8: Male Life Expectancy at Birth
A9: Years | B9: 2017-19 | C9: 2018-20 | D9: 2019-21 | E9: 2020-22 | F9: 2021-23
A10: Northern Ireland | B10: 78.818762 | C10: 78.733213 | D10: 78.476598 | E10: 78.425672 | F10: 78.763745
A11: Belfast LGD | B11: 76.076243 | C11: 75.783594 | D11: 75.576075 | E11: 75.800228 | F11: 76.535317 | G11: =H11 -> -1 | H11: -1
A12: Belfast LGD Deprived | B12: 71.356366 | C12: 70.655457 | D12: 70.043171 | E12: 70.763904 | F12: 71.846197 | G12: =H12 -> -1 | H12: -1
A13: Belfast LGD-NI Gap | B13: 2.742519 | C13: 2.9496194 | D13: 2.9005224 | E13: 2.6254444 | F13: 2.2284279
A14: Belfast LGD Deprivation Gap | B14: 4.7198774 | C14: 5.1281372 | D14: 5.5329046 | E14: 5.0363234 | F14: 4.6891197
A15: Balmoral | B15: 80.713292 | C15: 80.496 | D15: 79.830951 | E15: 79.625801 | F15: 80.623086
A16: Black Mountain | B16: 73.549136 | C16: 74.108785 | D16: 73.256465 | E16: 72.752832 | F16: 73.199965
A17: Botanic | B17: 76.977727 | C17: 77.921907 | D17: 78.053273 | E17: 78.289443 | F17: 78.095969
A18: Castle | B18: 74.729517 | C18: 73.880725 | D18: 74.355001 | E18: 74.557406 | F18: 75.536138
A19: Collin | B19: 77.234558 | C19: 76.332712 | D19: 76.717235 | E19: 76.695904 | F19: 77.288091
A20: Court | B20: 71.655483 | C20: 70.9334 | D20: 71.042609 | E20: 72.673371 | F20: 74.303166
A21: Lisnasharragh | B21: 79.778401 | C21: 79.403392 | D21: 79.19428 | E21: 79.670375 | F21: 79.277545
A22: Oldpark | B22: 73.285816 | C22: 73.008143 | D22: 72.069885 | E22: 72.471556 | F22: 73.222383
A23: Ormiston | B23: 78.875016 | C23: 79.097943 | D23: 79.28945 | E23: 79.171132 | F23: 79.955055
A24: Titanic | B24: 76.241313 | C24: 74.664618 | D24: 73.833228 | E24: 73.864024 | F24: 75.646855
A26: Female Life Expectancy at Birth
A27: Years | B27: 2017-19 | C27: 2018-20 | D27: 2019-21 | E27: 2020-22 | F27: 2021-23
A28: Northern Ireland | B28: 82.58255 | C28: 82.425041 | D28: 82.289751 | E28: 82.255854 | F28: 82.485164
A29: Belfast LGD | B29: 80.815815 | C29: 80.361793 | D29: 80.367292 | E29: 80.374512 | F29: 80.554214 | G29: =H29 -> -1 | H29: -1
A30: Belfast LGD Deprived | B30: 76.776199 | C30: 76.390477 | D30: 76.551022 | E30: 76.945563 | F30: 76.33963 | G30: =H30 -> -1 | H30: -1
A31: Belfast LGD-NI Gap | B31: 1.7667353 | C31: 2.0632476 | D31: 1.9224586 | E31: 1.8813415 | F31: 1.93095
A32: Belfast LGD Deprivation Gap | B32: 4.039616 | C32: 3.9713158 | D32: 3.8162703 | E32: 3.4289493 | F32: 4.2145838
A33: Balmoral | B33: 84.937706 | C33: 84.32488 | D33: 84.191666 | E33: 84.424848 | F33: 84.348469
A34: Black Mountain | B34: 79.030225 | C34: 78.671644 | D34: 78.371352 | E34: 78.265127 | F34: 78.356484
A35: Botanic | B35: 82.920803 | C35: 82.918094 | D35: 82.538627 | E35: 82.642369 | F35: 82.317322
A36: Castle | B36: 81.36179 | C36: 80.188779 | D36: 79.588959 | E36: 80.162402 | F36: 80.185619
A37: Collin | B37: 82.767517 | C37: 82.893015 | D37: 81.919468 | E37: 79.710448 | F37: 79.267268
A38: Court | B38: 76.398664 | C38: 75.678582 | D38: 76.383 | E38: 76.681672 | F38: 76.53911
A39: Lisnasharragh | B39: 82.445104 | C39: 81.497777 | D39: 82.447103 | E39: 82.001966 | F39: 82.934594
A40: Oldpark | B40: 79.425877 | C40: 78.675904 | D40: 78.105731 | E40: 78.451626 | F40: 78.443956
A41: Ormiston | B41: 83.26942 | C41: 83.343441 | D41: 83.256947 | E41: 83.466501 | F41: 84.04141
A42: Titanic | B42: 78.169739 | C42: 78.521974 | D42: 79.394086 | E42: 79.774656 | F42: 80.628657
A44: Male Life Expectancy at Age 65
...

Sheet Causeway Coast & Glens
A1: CAUSEWAY COAST & GLENS LOCAL GOVERNMENT DISTRICT
H3: RAG Comparison
A4: Key: | B4: Worse than | C4: -1 | D4: Similar to | E4: 0 | F4: Better than | G4: 1
A5: Service-based indicators Key: | B5: Lower than | C5: -1 | D5: Similar to | E5: 0 | F5: Higher than | G5: 1
A6: Note: Area values are compared to Northern Ireland, Area's deprived areas are compared to Area Average
A8: Male Life Expectancy at Birth
A9: Years | B9: 2017-19 | C9: 2018-20 | D9: 2019-21 | E9: 2020-22 | F9: 2021-23
A10: Northern Ireland | B10: 78.818762 | C10: 78.733213 | D10: 78.476598 | E10: 78.425672 | F10: 78.763745
A11: Causeway Coast & Glens LGD | B11: 79.423344 | C11: 79.622662 | D11: 79.39846 | E11: 79.133139 | F11: 79.127617 | G11: =H11 -> 0 | H11: 0
A12: Causeway Coast & Glens LGD Deprived | B12: 75.838137 | C12: 77.159116 | D12: 76.510643 | E12: 76.260564 | F12: 76.236294 | G12: =H12 -> -1 | H12: -1
A13: Causeway Coast & Glens LGD-NI Gap | B13: -0.6045823 | C13: -0.88944915 | D13: -0.92186226 | E13: -0.70746722 | F13: -0.36387259
A14: Causeway Coast & Glens LGD Deprivation Gap | B14: 3.5852077 | C14: 2.463546 | D14: 2.8878164 | E14: 2.8725756 | F14: 2.8913238
A15: Ballymoney | B15: 78.653973 | C15: 78.340177 | D15: 79.58199 | E15: 79.441113 | F15: 80.128869 | H15: 0
A16: Bann | B16: 82.070415 | C16: 81.932775 | D16: 80.976438 | E16: 80.76548 | F16: 81.266322 | H16: 1
A17: Benbradagh | B17: 77.930215 | C17: 78.972264 | D17: 80.115693 | E17: 80.640595 | F17: 80.477481 | H17: 0
A18: Causeway | B18: 80.142214 | C18: 80.698097 | D18: 79.805345 | E18: 79.090993 | F18: 78.830501 | H18: 0
A19: Coleraine | B19: 78.251939 | C19: 78.930626 | D19: 78.493986 | E19: 78.175367 | F19: 77.974165 | H19: 0
A20: Limavady | B20: 79.672954 | C20: 79.014039 | D20: 78.051369 | E20: 77.14884 | F20: 77.888942 | H20: 0
A21: The Glens | B21: 80.231955 | C21: 80.165567 | D21: 79.517553 | E21: 79.279845 | F21: 78.524824 | H21: 0
A23: Female Life Expectancy at Birth
A24: Years | B24: 2017-19 | C24: 2018-20 | D24: 2019-21 | E24: 2020-22 | F24: 2021-23
A25: Northern Ireland | B25: 82.58255 | C25: 82.425041 | D25: 82.289751 | E25: 82.255854 | F25: 82.485164
A26: Causeway Coast & Glens LGD | B26: 82.816561 | C26: 82.562756 | D26: 82.391851 | E26: 82.649033 | F26: 82.770767 | G26: =H26 -> 0 | H26: 0
A27: Causeway Coast & Glens LGD Deprived | B27: 81.209565 | C27: 80.063733 | D27: 80.065304 | E27: 80.321295 | F27: 80.545543 | G27: =H27 -> -1 | H27: -1
A28: Causeway Coast & Glens LGD-NI Gap | B28: -0.23401121 | C28: -0.13771534 | D28: -0.10209979 | E28: -0.39317912 | F28: -0.28560317
A29: Causeway Coast & Glens LGD Deprivation Gap | B29: 1.6069961 | C29: 2.499023 | D29: 2.3265469 | E29: 2.3277382 | F29: 2.2252234
A30: Ballymoney | B30: 83.006374 | C30: 83.259131 | D30: 83.564783 | E30: 84.139096 | F30: 84.394451 | H30: 0
A31: Bann | B31: 85.861149 | C31: 85.425619 | D31: 85.049148 | E31: 84.583954 | F31: 84.099537 | H31: 0
A32: Benbradagh | B32: 85.082576 | C32: 83.968141 | D32: 82.252764 | E32: 82.189196 | F32: 82.178433 | H32: 0
A33: Causeway | B33: 83.010734 | C33: 82.980868 | D33: 82.515479 | E33: 82.525008 | F33: 82.628959 | H33: 0
A34: Coleraine | B34: 81.355553 | C34: 81.152865 | D34: 81.836915 | E34: 82.384545 | F34: 82.219104 | H34: 0
A35: Limavady | B35: 81.18965 | C35: 80.463351 | D35: 80.424917 | E35: 80.946941 | F35: 80.990283 | H35: 0
A36: The Glens | B36: 82.812423 | C36: 82.322939 | D36: 82.06685 | E36: 82.143764 | F36: 83.242206 | H36: 0
A38: Male Life Expectancy at Age 65
A39: Years | B39: 2017-19 | C39: 2018-20 | D39: 2019-21 | E39: 2020-22 | F39: 2021-23
A40: Northern Ireland | B40: 18.536761 | C40: 18.484435 | D40: 18.365174 | E40: 18.304984 | F40: 18.506212
A41: Causeway Coast & Glens LGD | B41: 18.964471 | C41: 18.814847 | D41: 18.645247 | E41: 18.826523 | F41: 18.665901 | G41: =H41 -> 0 | H41: 0
A42: Causeway Coast & Glens LGD Deprived | B42: 17.594185 | C42: 18.065086 | D42: 18.257945 | E42: 18.191298 | F42: 18.17569 | G42: =H42 -> 0 | H42: 0
A43: Causeway Coast & Glens LGD-NI Gap | B43: -0.42770997 | C43: -0.33041232 | D43: -0.28007324 | E43: -0.52153944 | F43: -0.15968925
A44: Causeway Coast & Glens LGD Deprivation Gap | B44: 1.3702863 | C44: 0.74976088 | D44: 0.38730211 | E44: 0.63522568 | F44: 0.4902112
...

Sheet Derry City & Strabane
A1: DERRY CITY & STRABANE LOCAL GOVERNMENT DISTRICT
H3: RAG Comparison
A4: Key: | B4: Worse than | C4: -1 | D4: Similar to | E4: 0 | F4: Better than | G4: 1
A5: Service-based indicators Key: | B5: Lower than | C5: -1 | D5: Similar to | E5: 0 | F5: Higher than | G5: 1
A6: Note: Area values are compared to Northern Ireland, Area's deprived areas are compared to Area Average
A8: Male Life Expectancy at Birth
A9: Years | B9: 2017-19 | C9: 2018-20 | D9: 2019-21 | E9: 2020-22 | F9: 2021-23
A10: Northern Ireland | B10: 78.818762 | C10: 78.733213 | D10: 78.476598 | E10: 78.425672 | F10: 78.763745
A11: Derry City & Strabane LGD | B11: 77.759745 | C11: 77.99887 | D11: 77.316478 | E11: 77.515837 | F11: 77.421744 | G11: =H11 -> -1 | H11: -1
A12: Derry City & Strabane LGD Deprived | B12: 72.508377 | C12: 72.32713 | D12: 71.091095 | E12: 71.556088 | F12: 72.240508 | G12: =H12 -> -1 | H12: -1
A13: Derry City & Strabane LGD-NI Gap | B13: 1.0590172 | C13: 0.73434357 | D13: 1.1601193 | E13: 0.90983505 | F13: 1.3420012
A14: Derry City & Strabane LGD Deprivation Gap | B14: 5.2513681 | C14: 5.6717396 | D14: 6.2253832 | E14: 5.9597489 | F14: 5.181236
A15: Ballyarnett | B15: 76.604835 | C15: 76.962897 | D15: 76.109534 | E15: 77.957765 | F15: 78.025292 | H15: 0
A16: Derg | B16: 79.972853 | C16: 79.930771 | D16: 78.509383 | E16: 78.694569 | F16: 79.07725 | H16: 0
A17: Faughan | B17: 80.390538 | C17: 80.315299 | D17: 79.657365 | E17: 79.774063 | F17: 79.452739 | H17: 0
A18: Foyleside | B18: 78.330249 | C18: 77.783163 | D18: 76.722979 | E18: 76.158276 | F18: 75.914464 | H18: 0
A19: Sperrin | B19: 79.78928 | C19: 79.762187 | D19: 79.453732 | E19: 79.480439 | F19: 79.256937 | H19: 0
A20: The Moor | B20: 72.68575 | C20: 73.590766 | D20: 72.508716 | E20: 72.118589 | F20: 72.588936 | H20: -1
A21: Waterside | B21: 77.049805 | C21: 77.885391 | D21: 77.973805 | E21: 77.986534 | F21: 77.330769 | H21: 0
A23: Female Life Expectancy at Birth
A24: Years | B24: 2017-19 | C24: 2018-20 | D24: 2019-21 | E24: 2020-22 | F24: 2021-23
A25: Northern Ireland | B25: 82.58255 | C25: 82.425041 | D25: 82.289751 | E25: 82.255854 | F25: 82.485164
A26: Derry City & Strabane LGD | B26: 81.492538 | C26: 81.661091 | D26: 81.227256 | E26: 81.515383 | F26: 81.269617 | G26: =H26 -> -1 | H26: -1
A27: Derry City & Strabane LGD Deprived | B27: 78.687565 | C27: 78.915308 | D27: 78.300941 | E27: 78.024601 | F27: 77.630337 | G27: =H27 -> -1 | H27: -1
A28: Derry City & Strabane LGD-NI Gap | B28: 1.0900125 | C28: 0.76395015 | D28: 1.062495 | E28: 0.74047136 | F28: 1.2155464
A29: Derry City & Strabane LGD Deprivation Gap | B29: 2.804973 | C29: 2.7457831 | D29: 2.9263146 | E29: 3.4907813 | F29: 3.6392805
A30: Ballyarnett | B30: 82.207325 | C30: 82.501742 | D30: 81.933978 | E30: 81.6643 | F30: 80.530185 | H30: 0
A31: Derg | B31: 83.716061 | C31: 83.658327 | D31: 83.498473 | E31: 82.91138 | F31: 82.920936 | H31: 0
A32: Faughan | B32: 82.062147 | C32: 82.526503 | D32: 81.766065 | E32: 83.631254 | F32: 83.992508 | H32: 1
A33: Foyleside | B33: 81.638298 | C33: 81.68713 | D33: 81.321703 | E33: 81.511287 | F33: 80.955402 | H33: 0
A34: Sperrin | B34: 81.77906 | C34: 81.805704 | D34: 81.739622 | E34: 81.88082 | F34: 82.247482 | H34: 0
A35: The Moor | B35: 79.690379 | C35: 80.059384 | D35: 79.165017 | E35: 79.688574 | F35: 78.995788 | H35: -1
A36: Waterside | B36: 80.643706 | C36: 80.603194 | D36: 80.210106 | E36: 80.537337 | F36: 80.227777 | H36: 0
A38: Male Life Expectancy at Age 65
A39: Years | B39: 2017-19 | C39: 2018-20 | D39: 2019-21 | E39: 2020-22 | F39: 2021-23
A40: Northern Ireland | B40: 18.536761 | C40: 18.484435 | D40: 18.365174 | E40: 18.304984 | F40: 18.506212
A41: Derry City & Strabane LGD | B41: 17.917023 | C41: 18.134413 | D41: 17.895306 | E41: 18.096752 | F41: 17.884461 | G41: =H41 -> -1 | H41: -1
A42: Derry City & Strabane LGD Deprived | B42: 15.972851 | C42: 16.07119 | D42: 16.106571 | E42: 15.898263 | F42: 16.04131 | G42: =H42 -> -1 | H42: -1
A43: Derry City & Strabane LGD-NI Gap | B43: 0.61973824 | C43: 0.35002167 | D43: 0.46986766 | E43: 0.20823217 | F43: 0.62175102
A44: Derry City & Strabane LGD Deprivation Gap | B44: 1.9441723 | C44: 2.0632229 | D44: 1.7887351 | E44: 2.1984886 | F44: 1.8431509
...

Sheet Fermanagh & Omagh
A1: FERMANAGH & OMAGH LOCAL GOVERNMENT DISTRICT
H3: RAG Comparison
A4: Key: | B4: Worse than | C4: -1 | D4: Similar to | E4: 0 | F4: Better than | G4: 1
A5: Service-based indicators Key: | B5: Lower than | C5: -1 | D5: Similar to | E5: 0 | F5: Higher than | G5: 1
A6: Note: Area values are compared to Northern Ireland, Area's deprived areas are compared to Area Average
A8: Male Life Expectancy at Birth
A9: Years | B9: 2017-19 | C9: 2018-20 | D9: 2019-21 | E9: 2020-22 | F9: 2021-23
A10: Northern Ireland | B10: 78.818762 | C10: 78.733213 | D10: 78.476598 | E10: 78.425672 | F10: 78.763745
A11: Fermanagh & Omagh LGD | B11: 79.344408 | C11: 79.180131 | D11: 78.959127 | E11: 79.033295 | F11: 79.635419 | G11: =H11 -> 1 | H11: 1
A12: Fermanagh & Omagh LGD Deprived | B12: 77.90158 | C12: 78.036496 | D12: 77.619953 | E12: 76.511523 | F12: 76.558035 | G12: =H12 -> -1 | H12: -1
A13: Fermanagh & Omagh LGD-NI Gap | B13: -0.52564645 | C13: -0.44691803 | D13: -0.48252979 | E13: -0.60762284 | F13: -0.87167452
A14: Fermanagh & Omagh LGD Deprivation Gap | B14: 1.4428289 | C14: 1.1436348 | D14: 1.3391745 | E14: 2.521772 | F14: 3.0773841
A15: Enniskillen | B15: 77.705701 | C15: 78.398961 | D15: 78.434935 | E15: 78.95305 | F15: 80.022791 | H15: 0
A16: Erne East | B16: 79.837919 | C16: 79.587696 | D16: 79.228116 | E16: 77.964551 | F16: 78.347002 | H16: 0
A17: Erne North | B17: 79.967486 | C17: 80.363762 | D17: 78.971701 | E17: 79.119067 | F17: 79.386611 | H17: 0
A18: Erne West | B18: 81.429608 | C18: 80.419346 | D18: 81.036046 | E18: 80.718065 | F18: 82.34795 | H18: 1
A19: Mid Tyrone | B19: 80.333287 | C19: 79.825256 | D19: 79.383444 | E19: 79.79783 | F19: 80.27772 | H19: 0
A20: Omagh | B20: 77.140741 | C20: 77.121515 | D20: 77.137733 | E20: 76.81044 | F20: 76.894197 | H20: -1
A21: West Tyrone | B21: 79.849131 | C21: 79.450364 | D21: 79.085269 | E21: 80.473706 | F21: 80.844673 | H21: 0
A23: Female Life Expectancy at Birth
A24: Years | B24: 2017-19 | C24: 2018-20 | D24: 2019-21 | E24: 2020-22 | F24: 2021-23
A25: Northern Ireland | B25: 82.58255 | C25: 82.425041 | D25: 82.289751 | E25: 82.255854 | F25: 82.485164
A26: Fermanagh & Omagh LGD | B26: 83.256415 | C26: 83.299961 | D26: 82.702917 | E26: 82.783601 | F26: 83.056101 | G26: =H26 -> 0 | H26: 0
A27: Fermanagh & Omagh LGD Deprived | B27: 81.209554 | C27: 80.841768 | D27: 79.948363 | E27: 80.50505 | F27: 81.317367 | G27: =H27 -> 0 | H27: 0
A28: Fermanagh & Omagh LGD-NI Gap | B28: -0.67386503 | C28: -0.87491967 | D28: -0.41316553 | E28: -0.52774683 | F28: -0.57093711
A29: Fermanagh & Omagh LGD Deprivation Gap | B29: 2.0468609 | C29: 2.4581926 | D29: 2.7545534 | E29: 2.278551 | F29: 1.7387341
A30: Enniskillen | B30: 83.542616 | C30: 83.140972 | D30: 82.243483 | E30: 81.838875 | F30: 82.41412 | H30: 0
A31: Erne East | B31: 82.903412 | C31: 84.072415 | D31: 82.843139 | E31: 83.097049 | F31: 82.348256 | H31: 0
A32: Erne North | B32: 83.557574 | C32: 84.427796 | D32: 83.728511 | E32: 82.886307 | F32: 83.849953 | H32: 0
A33: Erne West | B33: 84.382866 | C33: 83.818131 | D33: 82.728731 | E33: 83.093357 | F33: 83.491916 | H33: 0
A34: Mid Tyrone | B34: 83.890823 | C34: 82.629602 | D34: 82.01902 | E34: 83.040108 | F34: 83.067976 | H34: 0
A35: Omagh | B35: 80.97575 | C35: 81.927457 | D35: 82.563476 | E35: 82.365175 | F35: 82.608023 | H35: 0
A36: West Tyrone | B36: 84.552431 | C36: 83.895543 | D36: 82.931433 | E36: 83.373204 | F36: 83.829047 | H36: 0
A38: Male Life Expectancy at Age 65
A39: Years | B39: 2017-19 | C39: 2018-20 | D39: 2019-21 | E39: 2020-22 | F39: 2021-23
A40: Northern Ireland | B40: 18.536761 | C40: 18.484435 | D40: 18.365174 | E40: 18.304984 | F40: 18.506212
A41: Fermanagh & Omagh LGD | B41: 18.821042 | C41: 18.804744 | D41: 18.604377 | E41: 18.839327 | F41: 18.908507 | G41: =H41 -> 0 | H41: 0
A42: Fermanagh & Omagh LGD Deprived | B42: 19.022692 | C42: 18.593893 | D42: 18.335409 | E42: 17.911474 | F42: 18.164877 | G42: =H42 -> 0 | H42: 0
A43: Fermanagh & Omagh LGD-NI Gap | B43: -0.28428102 | C43: -0.32030951 | D43: -0.23920375 | E43: -0.53434355 | F43: -0.40229551
A44: Fermanagh & Omagh LGD Deprivation Gap | B44: -0.20164927 | C44: 0.21085109 | D44: 0.26896819 | E44: 0.92785345 | F44: 0.74362985
...

Sheet Lisburn & Castlereagh
A1: LISBURN & CASTLEREAGH LOCAL GOVERNMENT DISTRICT
H3: RAG Comparison
A4: Key: | B4: Worse than | C4: -1 | D4: Similar to | E4: 0 | F4: Better than | G4: 1
A5: Service-based indicators Key: | B5: Lower than | C5: -1 | D5: Similar to | E5: 0 | F5: Higher than | G5: 1
A6: Note: Area values are compared to Northern Ireland, Area's deprived areas are compared to Area Average
A8: Male Life Expectancy at Birth
A9: Years | B9: 2017-19 | C9: 2018-20 | D9: 2019-21 | E9: 2020-22 | F9: 2021-23
A10: Northern Ireland | B10: 78.818762 | C10: 78.733213 | D10: 78.476598 | E10: 78.425672 | F10: 78.763745
A11: Lisburn & Castlereagh LGD | B11: 80.215207 | C11: 80.374387 | D11: 80.349529 | E11: 80.434956 | F11: 80.876746 | G11: =H11 -> 1 | H11: 1
A12: Lisburn & Castlereagh LGD Deprived | B12: 76.300695 | C12: 77.391385 | D12: 77.238087 | E12: 77.201199 | F12: 77.270388 | G12: =H12 -> -1 | H12: -1
A13: Lisburn & Castlereagh LGD-NI Gap | B13: -1.396445 | C13: -1.6411738 | D13: -1.8729311 | E13: -2.0092843 | F13: -2.1130015
A14: Lisburn & Castlereagh LGD Deprivation Gap | B14: 3.9145124 | C14: 2.9830016 | D14: 3.1114418 | E14: 3.2337575 | F14: 3.6063582
A15: Castlereagh East | B15: 80.397947 | C15: 80.291867 | D15: 80.41346 | E15: 80.400228 | F15: 81.166441 | H15: 0
A16: Castlereagh South | B16: 82.248927 | C16: 82.002424 | D16: 82.105108 | E16: 81.233337 | F16: 82.054426 | H16: 0
A17: Downshire East | B17: 82.50343 | C17: 83.53117 | D17: 82.456026 | E17: 82.65235 | F17: 82.547325 | H17: 0
A18: Downshire West | B18: 81.597699 | C18: 82.097037 | D18: 81.158955 | E18: 81.292071 | F18: 80.591128 | H18: 0
A19: Killultagh | B19: 80.290052 | C19: 80.52909 | D19: 81.580527 | E19: 82.456595 | F19: 82.949183 | H19: 1
A20: Lisburn North | B20: 78.139248 | C20: 77.940015 | D20: 78.736602 | E20: 78.730721 | F20: 79.819809 | H20: 0
A21: Lisburn South | B21: 77.942644 | C21: 78.323057 | D21: 77.737539 | E21: 77.900629 | F21: 78.426239 | H21: -1
A23: Female Life Expectancy at Birth
A24: Years | B24: 2017-19 | C24: 2018-20 | D24: 2019-21 | E24: 2020-22 | F24: 2021-23
A25: Northern Ireland | B25: 82.58255 | C25: 82.425041 | D25: 82.289751 | E25: 82.255854 | F25: 82.485164
